Python 3.8.2 (tags/v3.8.2:7b3ab59, Feb 25 2020, 22:45:29) [MSC v.1916 32 bit (Intel)] on win32
Type "help", "copyright", "credits" or "license()" for more information.
>>> print()

>>> 
== RESTART: C:/Users/perry/AppData/Local/Programs/Python/Python38-32/Listas.py =
False
True
True
False
True
[31, 28, 31, 30, 31, 30, 31, 30, 31, 30, 31, 30, 31]
31
31
30
[['cero', 0], ['uno', 1], ['dos', 2], ['tres', 3], ['cuatro', 4], ['x', 5]]
['cero', 0]
['uno', 1]
dos
2
uno
1
Traceback (most recent call last):
  File "C:/Users/perry/AppData/Local/Programs/Python/Python38-32/Listas.py", line 19, in <module>
    print(lista_diasDelMes[1][2])
IndexError: list index out of range
>>> 
== RESTART: C:/Users/perry/AppData/Local/Programs/Python/Python38-32/Tuplas.py =
(31, 28, 31, 30, 31, 30, 31, 30, 31, 30, 31, 30, 31)
31
30
28
[['cero', 0], ['uno', 1], ['dos', 2], ['tres', 3], ['cuatro', 4], ['x', 5]]
['cero', 0]
['uno', 1]
dos
2
uno
1
Traceback (most recent call last):
  File "C:/Users/perry/AppData/Local/Programs/Python/Python38-32/Tuplas.py", line 14, in <module>
    print(tupla_diasDelMes[1][2])
IndexError: list index out of range
>>> 
= RESTART: C:/Users/perry/AppData/Local/Programs/Python/Python38-32/Diccionarios.py
{'hidrogeno': 1, 'helio': 2, 'carbon': 6}
1
{'hidrogeno': 1, 'helio': 2, 'carbon': 6, 'litio': 3, 'nitrogeno': 6}
Traceback (most recent call last):
  File "C:/Users/perry/AppData/Local/Programs/Python/Python38-32/Diccionarios.py", line 9, in <module>
    elemrntos2['He']={'name': 'Helium', 'number': 2, 'weight': 4.002602}
NameError: name 'elemrntos2' is not defined
>>> 
= RESTART: C:/Users/perry/AppData/Local/Programs/Python/Python38-32/Funciones.py
holaJJ
el cuadrado de 5 es 25
4 8 16
4 16
>>> 
= RESTART: C:/Users/perry/AppData/Local/Programs/Python/Python38-32/VariablesGlobales.py
Global
Global
Traceback (most recent call last):
  File "C:/Users/perry/AppData/Local/Programs/Python/Python38-32/VariablesGlobales.py", line 9, in <module>
    funcion_v3()
NameError: name 'funcion_v3' is not defined
>>> 